Traceback (most recent call last):
  File "/nfs/turbo/umms-drjieliu/proj/prompt_re/kg_embeddings/train_hgt_lp_binary.py", line 12, in <module>
    from models import *
  File "/nfs/turbo/umms-drjieliu/proj/prompt_re/kg_embeddings/models.py", line 2, in <module>
    import dgl
  File "/home/hyhao/.conda/envs/kg/lib/python3.9/site-packages/dgl/__init__.py", line 16, in <module>
    from .backend import backend_name, load_backend  # usort: skip
  File "/home/hyhao/.conda/envs/kg/lib/python3.9/site-packages/dgl/backend/__init__.py", line 122, in <module>
    load_backend(get_preferred_backend())
  File "/home/hyhao/.conda/envs/kg/lib/python3.9/site-packages/dgl/backend/__init__.py", line 51, in load_backend
    from .._ffi.base import load_tensor_adapter  # imports DGL C library
  File "/home/hyhao/.conda/envs/kg/lib/python3.9/site-packages/dgl/_ffi/base.py", line 50, in <module>
    _LIB, _LIB_NAME, _DIR_NAME = _load_lib()
  File "/home/hyhao/.conda/envs/kg/lib/python3.9/site-packages/dgl/_ffi/base.py", line 39, in _load_lib
    lib = ctypes.CDLL(lib_path[0])
  File "/home/hyhao/.conda/envs/kg/lib/python3.9/ctypes/__init__.py", line 382, in __init__
    self._handle = _dlopen(self._name, mode)
OSError: libcudart.so.11.0: cannot open shared object file: No such file or directory
